Workbook

Sheet Índice
A1: DOE — SMART PACKAGING LINE
A2: Weight-based kit verification · Capstone · TE Connectivity
A4: ÍNDICE DEL DOCUMENTO
A5: # | B5: Sección | C5: Hoja | D5: Propósito
A6: 0 | B6: Setup | C6: Instructions | D6: Cómo usar este documento
C7: Components | D7: Catálogo de componentes (n=30)
C8: Recipes | D8: Recetas R3, R4, R6
C9: INFO Muestras Componentes | D9: Análisis de potencia
A10: 1 | B10: Documentación | C10: Documentación | D10: Teoría, fórmulas, fuentes de los 10 métodos
A11: 2 | B11: Métodos base | C11: Runs 1.0 20262904 | D11: k=3, déficit absoluto
C12: Runs 1.0 + 3.5 sigma | D12: k=3.5
C13: Runs 1.0 + 6 sigma | D13: k=6 (Six Sigma)
C14: Runs Z score | D14: Déficit normalizado por σ
C15: Runs Z score + 6 sigma | D15: Z-score con k=6
C16: Runs 1.1 | D16: Variante intermedia
A17: 3 | B17: Métodos estadísticos | C17: Runs Mahalanobis | D17: Mahalanobis (1936)
C18: Runs GMM | D18: Gaussian Mixture Model
A19: 5 | B19: Resultados | C19: Results | D19: Métricas detalladas
C20: Comparativa Final | D20: ★ Todos los métodos lado a lado
A21: 6 | B21: Datos adicionales | C21: Future Data 2 pieces missing | D21: Casos con 2 piezas faltantes
C22: Sheet1 | D22: Análisis auxiliar

Sheet Instructions
A1: DOE — SMART PACKAGING LINE INSPECTION
A2: Weight-based kit verification · Capstone · TE Connectivity
A4: COLOR CODE
A5: Yellow cells = inputs you must fill in
A6: Blue text = hardcoded input values
A7: Green text = links / references to other sheets
A8: Black text = formulas (do not edit)
A10: STEP-BY-STEP
A11: 1. COMPONENTS sheet
A12: Weigh 20 individual units of each component (S1, S2, W1, W2, N1, N2).
A13: Enter measured_mean_g and measured_std_g in yellow cells.
A14: This is critical — the model depends on these baselines.
... A50: • This is expected and validates the need for a Phase 2 complementary sensor.

Sheet Components
A1: component_id | B1: description | C1: measured_mean_g | D1: measured_std_g | E1: n_samples | F1: notes
A2: S1 | B2: Component type S1 | C2: 2.7533333 | D2: 0.0066089455 | E2: 30 | F2: Weigh 30 individual units BEFORE DOE
A3: S2 | B3: Component type S2 | C3: 4.036 | D3: 0.013796551 | E3: 30 | F3: Weigh 30 individual units BEFORE DOE
A4: W1 | B4: Component type W1 | C4: 0.99333333 | D4: 0.013978637 | E4: 30 | F4: Weigh 30 individual units BEFORE DOE
A5: W2 | B5: Component type W2 | C5: 4.5626667 | D5: 0.025179813 | E5: 30 | F5: Weigh 30 individual units BEFORE DOE
A6: N1 | B6: Component type N1 | C6: 1.1556667 | D6: 0.027628488 | E6: 30 | F6: Weigh 30 individual units BEFORE DOE
A7: N2 | B7: Component type N2 | C7: 1.3743333 | D7: 0.025145553 | E7: 30 | F7: Weigh 30 individual units BEFORE DOE
A8: PB | B8: Plastic Bag | C8: 0.967 | D8: 0.036345564 | E8: 30 | F8: Weigh 30 individual units BEFORE DOE

Sheet Recipes
A1: recipe_id | B1: components_list | C1: n_components | D1: n_S1 | E1: n_S2 | F1: n_W1 | G1: n_W2 | H1: n_N1 | I1: n_N2 | J1: expected_weight_g | K1: expected_variance | L1: expected_std_g | M1: lower_bound_3s | N1: upper_bound_3s
A2: R3 | B2: PB,S2,W2,N2 | C2: 3 | D2: 0 | E2: 1 | F2: 0 | G2: 1 | H2: 0 | I2: 1 | J2: =D2*Components!$C$2+E2*Components!$C$3+F2*Components!$C$4+G2*Components!$C$5+H2*Components!$C$6+I2*Components!$C$7+Components!$C$8 -> 10.94 | K2: =D2*Components!$D$2^2+E2*Components!$D$3^2+F2*Components!$D$4^2+G2*Components!$D$5^2+H2*Components!$D$6^2+I2*Components!$D$7^2+Components!$D$8^2 -> 0.0027776667 | L2: =SQRT(K2) -> 0.052703574 | M2: =J2-3*L2 -> 10.781889 | N2: =J2+3*L2 -> 11.098111
A3: R4 | B3: PB,S1,W1,N1,S2 | C3: 4 | D3: 1 | E3: 1 | F3: 1 | G3: 0 | H3: 1 | I3: 0 | J3: =D3*Components!$C$2+E3*Components!$C$3+F3*Components!$C$4+G3*Components!$C$5+H3*Components!$C$6+I3*Components!$C$7+Components!$C$8 -> 9.9053333 | K3: =D3*Components!$D$2^2+E3*Components!$D$3^2+F3*Components!$D$4^2+G3*Components!$D$5^2+H3*Components!$D$6^2+I3*Components!$D$7^2+Components!$D$8^2 -> 0.0025137586 | L3: =SQRT(K3) -> 0.050137397 | M3: =J3-3*L3 -> 9.7549211 | N3: =J3+3*L3 -> 10.055746
A4: R6 | B4: PB,S1,W1,W1,N2,N2,N1 | C4: 6 | D4: 1 | E4: 0 | F4: 2 | G4: 0 | H4: 1 | I4: 2 | J4: =D4*Components!$C$2+E4*Components!$C$3+F4*Components!$C$4+G4*Components!$C$5+H4*Components!$C$6+I4*Components!$C$7+Components!$C$8 -> 9.6113333 | K4: =D4*Components!$D$2^2+E4*Components!$D$3^2+F4*Components!$D$4^2+G4*Components!$D$5^2+H4*Components!$D$6^2+I4*Components!$D$7^2+Components!$D$8^2 -> 0.0037834138 | L4: =SQRT(K4) -> 0.061509461 | M4: =J4-3*L4 -> 9.426805 | N4: =J4+3*L4 -> 9.7958617

Sheet INFO Muestras Componentes
A1: Determinación de tamaño de muestra por potencia estadística | F1: Referencias a confirmar
A2: Probabilidad de equivocarte diciendo que dos componentes son diferentes cuando en realidad no lo son (Nivel de significancia, α) | B2: Probabilidad de detectar una diferencia real cuando sí existe (Potencia estadística, 1−β) | C2: Cuántas desviaciones estándar te alejas del centro para capturar el 95% de los datos en una curva normal (Valor crítico de dos colas, z_α/2) | D2: Cuántas desviaciones estándar te alejas del centro para capturar el 80% de los datos en una curva normal (Valor crítico de potencia, z_β) | F2: Montgomery, D.C. & Runger, G.C. (2014). Applied Statistics and Probability for Engineers (6th ed.). Wiley. Capítulo 10 — Inference for Two Samples Sección 10-2: Sample size determination for the two-sample t-test Ahí encuentras exactamente la fórmula n = 2σ²(z_α/2 + z_β)² / δ² con su derivación completa y tablas de OC curves. | G2: Cohen, J. (1988). Statistical Power Analysis for the Behavioral Sciences (2nd ed.). Lawrence Erlbaum. Capítulo 2 — The t-Test for Means Sección 2.2: The effect size index d Sección 2.4: Power tables and sample size determination Es el libro de referencia estándar para power analysis — define formalmente α, β, potencia y el cálculo de n para comparación de medias.
A3: 0.05 | B3: 0.8 | C3: =_xlfn.NORM.S.INV(1 - A3/2) -> 1.959964 | D3: =_xlfn.NORM.S.INV(B3) -> 0.84162123
G4: Si la celda es de este color verde, es modificable
A5: Par que se está comparando | B5: Qué tan separadas están las medias de los dos componentes (Diferencia mínima detectable, δ) | C5: Qué tanto varían juntos los dos componentes (Desviación estándar combinada, σ_pooled) | D5: Número mínimo de muestras (n) | E5: Notes
A6: S1/S2 | B6: =ABS(Components!C2-Components!C3) -> 1.2826667 | C6: =SQRT(((Components!D2^2)+(Components!D3^2))/2) -> 0.010817185 | D6: =ROUNDUP(2 * (C6^2) * ($C$3 + $D$3)^2 / (B6^2), 0) -> 1
A7: S1/W1 | B7: =ABS(Components!C2-Components!C4) -> 1.76 | C7: =SQRT(((Components!D2^2)+(Components!D4^2))/2) -> 0.010933445 | D7: =ROUNDUP(2 * (C7^2) * ($C$3 + $D$3)^2 / (B7^2), 0) -> 1
A8: S1/W2 | B8: =ABS(Components!C2-Components!C5) -> 1.8093333 | C8: =SQRT(((Components!D2^2)+(Components!D5^2))/2) -> 0.018407894 | D8: =ROUNDUP(2 * (C8^2) * ($C$3 + $D$3)^2 / (B8^2), 0) -> 1
A9: S1/N1 | B9: =ABS(Components!C2-Components!C6) -> 1.5976667 | C9: =SQRT(((Components!D2^2)+(Components!D6^2))/2) -> 0.020087452 | D9: =ROUNDUP(2 * (C9^2) * ($C$3 + $D$3)^2 / (B9^2), 0) -> 1
A10: S1/N2 | B10: =ABS(Components!C2-Components!C7) -> 1.379 | C10: =SQRT(((Components!D2^2)+(Components!D7^2))/2) -> 0.018384464 | D10: =ROUNDUP(2 * (C10^2) * ($C$3 + $D$3)^2 / (B10^2), 0) -> 1
A11: S2/W1 | B11: =ABS(Components!C3-Components!C4) -> 3.0426667 | C11: =SQRT(((Components!D3^2)+(Components!D4^2))/2) -> 0.013887893 | D11: =ROUNDUP(2 * (C11^2) * ($C$3 + $D$3)^2 / (B11^2), 0) -> 1
A12: S2/W2 | B12: =ABS(Components!C3-Components!C5) -> 0.52666667 | C12: =SQRT(((Components!D3^2)+(Components!D5^2))/2) -> 0.020302313 | D12: =ROUNDUP(2 * (C12^2) * ($C$3 + $D$3)^2 / (B12^2), 0) -> 1 | E12: Parecido
A13: S2/N1 | B13: =ABS(Components!C3-Components!C6) -> 2.8803333 | C13: =SQRT(((Components!D3^2)+(Components!D6^2))/2) -> 0.021836645 | D13: =ROUNDUP(2 * (C13^2) * ($C$3 + $D$3)^2 / (B13^2), 0) -> 1
A14: S2/N2 | B14: =ABS(Components!C3-Components!C7) -> 2.6616667 | C14: =SQRT(((Components!D3^2)+(Components!D7^2))/2) -> 0.020281071 | D14: =ROUNDUP(2 * (C14^2) * ($C$3 + $D$3)^2 / (B14^2), 0) -> 1
A15: W1/W2 | B15: =ABS(Components!C4-Components!C5) -> 3.5693333 | C15: =SQRT(((Components!D4^2)+(Components!D5^2))/2) -> 0.020364495 | D15: =ROUNDUP(2 * (C15^2) * ($C$3 + $D$3)^2 / (B15^2), 0) -> 1
A16: W1/N1 | B16: =ABS(Components!C4-Components!C6) -> 0.16233333 | C16: =SQRT(((Components!D4^2)+(Components!D6^2))/2) -> 0.02189447 | D16: =ROUNDUP(2 * (C16^2) * ($C$3 + $D$3)^2 / (B16^2), 0) -> 1 | E16: Más parecido
A17: W1/N2 | B17: =ABS(Components!C4-Components!C7) -> 0.381 | C17: =SQRT(((Components!D4^2)+(Components!D7^2))/2) -> 0.020343318 | D17: =ROUNDUP(2 * (C17^2) * ($C$3 + $D$3)^2 / (B17^2), 0) -> 1 | E17: Parecido
A18: W2/N1 | B18: =ABS(Components!C5-Components!C6) -> 3.407 | C18: =SQRT(((Components!D5^2)+(Components!D6^2))/2) -> 0.026432521 | D18: =ROUNDUP(2 * (C18^2) * ($C$3 + $D$3)^2 / (B18^2), 0) -> 1
A19: W2/N2 | B19: =ABS(Components!C5-Components!C7) -> 3.1883333 | C19: =SQRT(((Components!D5^2)+(Components!D7^2))/2) -> 0.025162689 | D19: =ROUNDUP(2 * (C19^2) * ($C$3 + $D$3)^2 / (B19^2), 0) -> 1
A20: N1/N2 | B20: =ABS(Components!C6-Components!C7) -> 0.21866667 | C20: =SQRT(((Components!D6^2)+(Components!D7^2))/2) -> 0.026416209 | D20: =ROUNDUP(2 * (C20^2) * ($C$3 + $D$3)^2 / (B20^2), 0) -> 1 | E20: Parecido
A22: Conclusión
A23: El análisis de determinación de tamaño de muestra por potencia estadística (α = 0.05, potencia = 0.80) aplicado a los 15 pares posibles entre los 6 componentes del sistema indica que el número mínimo de muestras requerido para detectar la diferencia mínima detectable entre cualquier par es n = 1 en todos los casos. El par más difícil de distinguir es W1/N1, con una diferencia mínima detectable de apenas 0.16g y una desviación estándar combinada de 0.02g. A pesar de ser el par más parecido del catálogo, la fórmula sigue arrojando n = 1, lo que confirma que incluso en el caso más desfavorable la diferencia entre medias supera ampliamente el ruido de medición a nivel de componente individual. Por lo tanto, el tamaño de calibración adoptado de n = 30 unidades por componente es estadísticamente conservador, está 30 veces por encima del mínimo requerido. Esto descarta que una calibración insuficiente sea la causa de los errores de identificación observados en la receta R6. La fuente de ambigüedad reside en otro nivel del sistema, no en los datos de calibración.

Sheet Documentación
A1: DOCUMENTACIÓN DE MÉTODOS DE CLASIFICACIÓN
A2: Cada método clasifica kits en dos niveles: L1 (OK/NG) y L2 (componente faltante si NG).
A4: 1. RUNS 1.0 — Z-score clásico con déficit absoluto
A5: Teoría | B5: Método clásico de Statistical Process Control (Shewhart, 1931). El kit es OK si su peso cae dentro de los límites de control μ ± k·σ. Si es NG, identifica la pieza faltante como aquella cuyo peso individual es más cercano al déficit observado.
A6: Fórmula L1 | B6: OK si |w − μ_kit| ≤ k·σ_kit, donde k=3 (3-sigma de Shewhart)
A7: Fórmula L2 | B7: componente_faltante = argmin over i of |déficit − μ_i|, donde déficit = μ_kit − w
A8: Fuente | B8: Shewhart, W.A. (1931). Economic Control of Quality of Manufactured Product. Van Nostrand. Montgomery, D.C. (2009). Introduction to Statistical Quality Control (6th ed.). Wiley. Capítulo 5.
A9: Desempeño | B9: L1: 99.05%, L2: 96.06% (mejor método actual en L2) | F9: → Runs 1.0 20262904
A11: 2. RUNS 1.0 + 3.5 SIGMA — Variante con umbral relajado
A12: Teoría | B12: Misma lógica que Runs 1.0 pero con k=3.5. Reduce falsos positivos a costa de potenciales falsos negativos. Útil cuando el costo de rechazar un kit bueno supera al de aceptar uno defectuoso.
A13: Fórmula L1 | B13: OK si |w − μ_kit| ≤ 3.5·σ_kit
A14: Fórmula L2 | B14: Igual que Runs 1.0
A15: Fuente | B15: Variante práctica del método de Shewhart. No tiene paper específico.
A16: Desempeño | B16: L1: 99.29%, L2: 96.06% | F16: → Runs 1.0 + 3.5 sigma
A18: 3. RUNS 1.0 + 6 SIGMA — Variante Six Sigma estricta
A19: Teoría | B19: Misma lógica con k=6 (Six Sigma). Minimiza falsos positivos hasta 3.4 por millón asumiendo normalidad perfecta. Usado en industrias de alta criticidad.
A20: Fórmula L1 | B20: OK si |w − μ_kit| ≤ 6·σ_kit
A21: Fórmula L2 | B21: Igual que Runs 1.0
A22: Fuente | B22: Harry, M.J., Schroeder, R. (2000). Six Sigma: The Breakthrough Management Strategy. Currency Doubleday. ISBN: 978-0385494373.
A23: Desempeño | B23: L1: 99.52%, L2: 96.06% | F23: → Runs 1.0 + 6 sigma
A25: 4. RUNS Z-SCORE — Déficit normalizado por σ del componente
A26: Teoría | B26: Variante donde la identificación L2 usa la distancia normalizada por la desviación estándar de cada componente. Penaliza componentes con σ pequeño (zona de aceptación más estrecha), lo que sesga la decisión en pares como W1/N1.
A27: Fórmula L1 | B27: OK si |w − μ_kit| ≤ k·σ_kit (mismo que Runs 1.0)
A28: Fórmula L2 | B28: componente_faltante = argmin over i of |déficit − μ_i| / σ_i
A29: Fuente | B29: Aplicación directa de z-score multivariable. Fundamento: Cox, D.R., Snell, E.J. (1989). Analysis of Binary Data (2nd ed.). Chapman & Hall.
A30: Desempeño | B30: L1: 99.05%, L2: 93.64% (peor que Runs 1.0 por la normalización) | F30: → Runs Z score
A32: 5. RUNS MAHALANOBIS — Distancia generalizada con corrección de sesgo
A33: Teoría | B33: Mahalanobis (1936) generalizó el z-score a múltiples variables considerando covarianzas. Con 1 variable, el método se reduce al z-score pero con dos mejoras importantes: (1) umbral calibrado por distribución F de Hotelling en lugar de k=3 arbitrario, (2) corrección de sesgo D² = D₁² − 2P/n para muestras finitas (eq. 4.12 del paper).
A34: Fórmula L1 | B34: D² = (w − μ_kit)² / σ²_kit − 2P/n; OK si D² ≤ T²_crit (Hotelling)
A35: Fórmula L2 | B35: Igual que Runs 1.0 (déficit absoluto)
A36: Fuente | B36: Mahalanobis, P.C. (1936). On the Generalised Distance in Statistics. Proc. Natl. Inst. Sci. India, 2(1), 49-55. Ecuaciones verificadas: 2.1, 4.11, 4.12, 4.31.
A37: Desempeño | B37: L1: 99.05%, L2: 96.06% (igual que Runs 1.0 con 1 variable; mejora estructural al añadir variables) | F37: → Runs Mahalanobis
A39: 6. RUNS GMM — Gaussian Mixture Model con flag AMBIGUOUS
A40: Teoría | B40: Cada hipótesis 'falta componente X' se modela como una distribución Gaussiana propia. Para un kit NG, evalúa la log-likelihood bajo cada hipótesis y normaliza con softmax. Genera probabilidades calibradas y detecta automáticamente kits ambiguos (margen < 0.15) para inspección manual sin reglas ad-hoc.
A41: Fórmula L1 | B41: Igual que Runs 1.0 (k=3)
A42: Fórmula L2 | B42: log L_i = −0.5·((déficit − μ_i)/σ_i)²; P_i = softmax(log L_i); componente = argmax P_i; AMBIGUOUS si P_top1 − P_top2 < 0.15
A43: Fuente | B43: McLachlan, G.J., Peel, D. (2000). Finite Mixture Models. Wiley. ISBN: 978-0471006268. Dempster, Laird, Rubin (1977). EM Algorithm. JRSS B, 39(1), 1-38.
A44: Desempeño | B44: L1: 99.05%, L2: 93.64%; detecta 2 casos AMBIGUOUS automáticamente | F44: → Runs GMM

Sheet Runs Distance + 3 Sigma
A1: 29-04-2026
A2: run_id | B2: execution_order | C2: recipe | D2: condition | E2: missing_component | F2: measured_weight_g | G2: measured_weight_w/PB | H2: notes | I2: expected_weight | J2: expected_std | K2: lower_bound | L2: upper_bound | M2: predicted_OK_NG | N2: L1_correct | O2: deficit | P2: match_S1 | Q2: match_S2 | R2: match_W1 | S2: match_W2 | T2: match_N1 | U2: match_N2 | V2: predicted_missing | W2: L2_correct | X2: 16 errores
A3: 1 | B3: 1 | C3: R3 | D3: OK | E3: NONE | F3: 9.91 | G3: =0.97+F3 -> 10.88 | I3: =VLOOKUP(C3,Recipes!$A$2:$N$4,10,FALSE()) -> 10.94 | J3: =VLOOKUP(C3,Recipes!$A$2:$N$4,12,FALSE()) -> 0.052703574 | K3: =I3-3*J3 -> 10.781889 | L3: =I3+3*J3 -> 11.098111 | M3: =IF(G3="","",IF(AND(G3>=K3,G3<=L3),"OK","NG")) -> OK | N3: =IF(M3="","",IF(M3=D3,1,0)) -> 1 | O3: =IF(G3="","",I3-G3) -> 0.06 | P3: =IF(G3="","",ABS(O3-Components!$C$2)) -> 2.6933333 | Q3: =IF(G3="","",ABS(O3-Components!$C$3)) -> 3.976 | R3: =IF(G3="","",ABS(O3-Components!$C$4)) -> 0.93333333 | S3: =IF(G3="","",ABS(O3-Components!$C$5)) -> 4.5026667 | T3: =IF(G3="","",ABS(O3-Components!$C$6)) -> 1.0956667 | U3: =IF(G3="","",ABS(O3-Components!$C$7)) -> 1.3143333 | V3: =IF(F3="","",IF(M3="OK","NONE",INDEX({"S1","S2","W1","W2","N1","N2"},MATCH(MIN(P3:U3),P3:U3,0)))) -> NONE | W3: =IF(G3="","",IF(V3=E3,1,0)) -> 1
A4: 2 | B4: 1 | C4: R3 | D4: OK | E4: NONE | F4: 10 | G4: =0.97+F4 -> 10.97 | I4: =VLOOKUP(C4,Recipes!$A$2:$N$4,10,FALSE()) -> 10.94 | J4: =VLOOKUP(C4,Recipes!$A$2:$N$4,12,FALSE()) -> 0.052703574 | K4: =I4-3*J4 -> 10.781889 | L4: =I4+3*J4 -> 11.098111 | M4: =IF(G4="","",IF(AND(G4>=K4,G4<=L4),"OK","NG")) -> OK | N4: =IF(M4="","",IF(M4=D4,1,0)) -> 1 | O4: =IF(G4="","",I4-G4) -> -0.03 | P4: =IF(G4="","",ABS(O4-Components!$C$2)) -> 2.7833333 | Q4: =IF(G4="","",ABS(O4-Components!$C$3)) -> 4.066 | R4: =IF(G4="","",ABS(O4-Components!$C$4)) -> 1.0233333 | S4: =IF(G4="","",ABS(O4-Components!$C$5)) -> 4.5926667 | T4: =IF(G4="","",ABS(O4-Components!$C$6)) -> 1.1856667 | U4: =IF(G4="","",ABS(O4-Components!$C$7)) -> 1.4043333 | V4: =IF(F4="","",IF(M4="OK","NONE",INDEX({"S1","S2","W1","W2","N1","N2"},MATCH(MIN(P4:U4),P4:U4,0)))) -> NONE | W4: =IF(G4="","",IF(V4=E4,1,0)) -> 1
A5: 3 | B5: 1 | C5: R3 | D5: OK | E5: NONE | F5: 10 | G5: =0.97+F5 -> 10.97 | I5: =VLOOKUP(C5,Recipes!$A$2:$N$4,10,FALSE()) -> 10.94 | J5: =VLOOKUP(C5,Recipes!$A$2:$N$4,12,FALSE()) -> 0.052703574 | K5: =I5-3*J5 -> 10.781889 | L5: =I5+3*J5 -> 11.098111 | M5: =IF(G5="","",IF(AND(G5>=K5,G5<=L5),"OK","NG")) -> OK | N5: =IF(M5="","",IF(M5=D5,1,0)) -> 1 | O5: =IF(G5="","",I5-G5) -> -0.03 | P5: =IF(G5="","",ABS(O5-Components!$C$2)) -> 2.7833333 | Q5: =IF(G5="","",ABS(O5-Components!$C$3)) -> 4.066 | R5: =IF(G5="","",ABS(O5-Components!$C$4)) -> 1.0233333 | S5: =IF(G5="","",ABS(O5-Components!$C$5)) -> 4.5926667 | T5: =IF(G5="","",ABS(O5-Components!$C$6)) -> 1.1856667 | U5: =IF(G5="","",ABS(O5-Components!$C$7)) -> 1.4043333 | V5: =IF(F5="","",IF(M5="OK","NONE",INDEX({"S1","S2","W1","W2","N1","N2"},MATCH(MIN(P5:U5),P5:U5,0)))) -> NONE | W5: =IF(G5="","",IF(V5=E5,1,0)) -> 1
A6: 4 | B6: 1 | C6: R3 | D6: OK | E6: NONE | F6: 9.91 | G6: =0.97+F6 -> 10.88 | I6: =VLOOKUP(C6,Recipes!$A$2:$N$4,10,FALSE()) -> 10.94 | J6: =VLOOKUP(C6,Recipes!$A$2:$N$4,12,FALSE()) -> 0.052703574 | K6: =I6-3*J6 -> 10.781889 | L6: =I6+3*J6 -> 11.098111 | M6: =IF(G6="","",IF(AND(G6>=K6,G6<=L6),"OK","NG")) -> OK | N6: =IF(M6="","",IF(M6=D6,1,0)) -> 1 | O6: =IF(G6="","",I6-G6) -> 0.06 | P6: =IF(G6="","",ABS(O6-Components!$C$2)) -> 2.6933333 | Q6: =IF(G6="","",ABS(O6-Components!$C$3)) -> 3.976 | R6: =IF(G6="","",ABS(O6-Components!$C$4)) -> 0.93333333 | S6: =IF(G6="","",ABS(O6-Components!$C$5)) -> 4.5026667 | T6: =IF(G6="","",ABS(O6-Components!$C$6)) -> 1.0956667 | U6: =IF(G6="","",ABS(O6-Components!$C$7)) -> 1.3143333 | V6: =IF(F6="","",IF(M6="OK","NONE",INDEX({"S1","S2","W1","W2","N1","N2"},MATCH(MIN(P6:U6),P6:U6,0)))) -> NONE | W6: =IF(G6="","",IF(V6=E6,1,0)) -> 1
A7: 5 | B7: 1 | C7: R3 | D7: OK | E7: NONE | F7: 10.04 | G7: =0.97+F7 -> 11.01 | I7: =VLOOKUP(C7,Recipes!$A$2:$N$4,10,FALSE()) -> 10.94 | J7: =VLOOKUP(C7,Recipes!$A$2:$N$4,12,FALSE()) -> 0.052703574 | K7: =I7-3*J7 -> 10.781889 | L7: =I7+3*J7 -> 11.098111 | M7: =IF(G7="","",IF(AND(G7>=K7,G7<=L7),"OK","NG")) -> OK | N7: =IF(M7="","",IF(M7=D7,1,0)) -> 1 | O7: =IF(G7="","",I7-G7) -> -0.07 | P7: =IF(G7="","",ABS(O7-Components!$C$2)) -> 2.8233333 | Q7: =IF(G7="","",ABS(O7-Components!$C$3)) -> 4.106 | R7: =IF(G7="","",ABS(O7-Components!$C$4)) -> 1.0633333 | S7: =IF(G7="","",ABS(O7-Components!$C$5)) -> 4.6326667 | T7: =IF(G7="","",ABS(O7-Components!$C$6)) -> 1.2256667 | U7: =IF(G7="","",ABS(O7-Components!$C$7)) -> 1.4443333 | V7: =IF(F7="","",IF(M7="OK","NONE",INDEX({"S1","S2","W1","W2","N1","N2"},MATCH(MIN(P7:U7),P7:U7,0)))) -> NONE | W7: =IF(G7="","",IF(V7=E7,1,0)) -> 1
A8: 6 | B8: 1 | C8: R3 | D8: OK | E8: NONE | F8: 9.84 | G8: =0.97+F8 -> 10.81 | I8: =VLOOKUP(C8,Recipes!$A$2:$N$4,10,FALSE()) -> 10.94 | J8: =VLOOKUP(C8,Recipes!$A$2:$N$4,12,FALSE()) -> 0.052703574 | K8: =I8-3*J8 -> 10.781889 | L8: =I8+3*J8 -> 11.098111 | M8: =IF(G8="","",IF(AND(G8>=K8,G8<=L8),"OK","NG")) -> OK | N8: =IF(M8="","",IF(M8=D8,1,0)) -> 1 | O8: =IF(G8="","",I8-G8) -> 0.13 | P8: =IF(G8="","",ABS(O8-Components!$C$2)) -> 2.6233333 | Q8: =IF(G8="","",ABS(O8-Components!$C$3)) -> 3.906 | R8: =IF(G8="","",ABS(O8-Components!$C$4)) -> 0.86333333 | S8: =IF(G8="","",ABS(O8-Components!$C$5)) -> 4.4326667 | T8: =IF(G8="","",ABS(O8-Components!$C$6)) -> 1.0256667 | U8: =IF(G8="","",ABS(O8-Components!$C$7)) -> 1.2443333 | V8: =IF(F8="","",IF(M8="OK","NONE",INDEX({"S1","S2","W1","W2","N1","N2"},MATCH(MIN(P8:U8),P8:U8,0)))) -> NONE | W8: =IF(G8="","",IF(V8=E8,1,0)) -> 1
A9: 7 | B9: 1 | C9: R3 | D9: OK | E9: NONE | F9: 9.9 | G9: =0.97+F9 -> 10.87 | I9: =VLOOKUP(C9,Recipes!$A$2:$N$4,10,FALSE()) -> 10.94 | J9: =VLOOKUP(C9,Recipes!$A$2:$N$4,12,FALSE()) -> 0.052703574 | K9: =I9-3*J9 -> 10.781889 | L9: =I9+3*J9 -> 11.098111 | M9: =IF(G9="","",IF(AND(G9>=K9,G9<=L9),"OK","NG")) -> OK | N9: =IF(M9="","",IF(M9=D9,1,0)) -> 1 | O9: =IF(G9="","",I9-G9) -> 0.07 | P9: =IF(G9="","",ABS(O9-Components!$C$2)) -> 2.6833333 | Q9: =IF(G9="","",ABS(O9-Components!$C$3)) -> 3.966 | R9: =IF(G9="","",ABS(O9-Components!$C$4)) -> 0.92333333 | S9: =IF(G9="","",ABS(O9-Components!$C$5)) -> 4.4926667 | T9: =IF(G9="","",ABS(O9-Components!$C$6)) -> 1.0856667 | U9: =IF(G9="","",ABS(O9-Components!$C$7)) -> 1.3043333 | V9: =IF(F9="","",IF(M9="OK","NONE",INDEX({"S1","S2","W1","W2","N1","N2"},MATCH(MIN(P9:U9),P9:U9,0)))) -> NONE | W9: =IF(G9="","",IF(V9=E9,1,0)) -> 1
A10: 8 | B10: 1 | C10: R3 | D10: OK | E10: NONE | F10: 9.92 | G10: =0.97+F10 -> 10.89 | I10: =VLOOKUP(C10,Recipes!$A$2:$N$4,10,FALSE()) -> 10.94 | J10: =VLOOKUP(C10,Recipes!$A$2:$N$4,12,FALSE()) -> 0.052703574 | K10: =I10-3*J10 -> 10.781889 | L10: =I10+3*J10 -> 11.098111 | M10: =IF(G10="","",IF(AND(G10>=K10,G10<=L10),"OK","NG")) -> OK | N10: =IF(M10="","",IF(M10=D10,1,0)) -> 1 | O10: =IF(G10="","",I10-G10) -> 0.05 | P10: =IF(G10="","",ABS(O10-Components!$C$2)) -> 2.7033333 | Q10: =IF(G10="","",ABS(O10-Components!$C$3)) -> 3.986 | R10: =IF(G10="","",ABS(O10-Components!$C$4)) -> 0.94333333 | S10: =IF(G10="","",ABS(O10-Components!$C$5)) -> 4.5126667 | T10: =IF(G10="","",ABS(O10-Components!$C$6)) -> 1.1056667 | U10: =IF(G10="","",ABS(O10-Components!$C$7)) -> 1.3243333 | V10: =IF(F10="","",IF(M10="OK","NONE",INDEX({"S1","S2","W1","W2","N1","N2"},MATCH(MIN(P10:U10),P10:U10,0)))) -> NONE | W10: =IF(G10="","",IF(V10=E10,1,0)) -> 1
A11: 9 | B11: 1 | C11: R3 | D11: OK | E11: NONE | F11: 9.95 | G11: =0.97+F11 -> 10.92 | I11: =VLOOKUP(C11,Recipes!$A$2:$N$4,10,FALSE()) -> 10.94 | J11: =VLOOKUP(C11,Recipes!$A$2:$N$4,12,FALSE()) -> 0.052703574 | K11: =I11-3*J11 -> 10.781889 | L11: =I11+3*J11 -> 11.098111 | M11: =IF(G11="","",IF(AND(G11>=K11,G11<=L11),"OK","NG")) -> OK | N11: =IF(M11="","",IF(M11=D11,1,0)) -> 1 | O11: =IF(G11="","",I11-G11) -> 0.02 | P11: =IF(G11="","",ABS(O11-Components!$C$2)) -> 2.7333333 | Q11: =IF(G11="","",ABS(O11-Components!$C$3)) -> 4.016 | R11: =IF(G11="","",ABS(O11-Components!$C$4)) -> 0.97333333 | S11: =IF(G11="","",ABS(O11-Components!$C$5)) -> 4.5426667 | T11: =IF(G11="","",ABS(O11-Components!$C$6)) -> 1.1356667 | U11: =IF(G11="","",ABS(O11-Components!$C$7)) -> 1.3543333 | V11: =IF(F11="","",IF(M11="OK","NONE",INDEX({"S1","S2","W1","W2","N1","N2"},MATCH(MIN(P11:U11),P11:U11,0)))) -> NONE | W11: =IF(G11="","",IF(V11=E11,1,0)) -> 1
A12: 10 | B12: 1 | C12: R3 | D12: OK | E12: NONE | F12: 9.87 | G12: =0.97+F12 -> 10.84 | I12: =VLOOKUP(C12,Recipes!$A$2:$N$4,10,FALSE()) -> 10.94 | J12: =VLOOKUP(C12,Recipes!$A$2:$N$4,12,FALSE()) -> 0.052703574 | K12: =I12-3*J12 -> 10.781889 | L12: =I12+3*J12 -> 11.098111 | M12: =IF(G12="","",IF(AND(G12>=K12,G12<=L12),"OK","NG")) -> OK | N12: =IF(M12="","",IF(M12=D12,1,0)) -> 1 | O12: =IF(G12="","",I12-G12) -> 0.1 | P12: =IF(G12="","",ABS(O12-Components!$C$2)) -> 2.6533333 | Q12: =IF(G12="","",ABS(O12-Components!$C$3)) -> 3.936 | R12: =IF(G12="","",ABS(O12-Components!$C$4)) -> 0.89333333 | S12: =IF(G12="","",ABS(O12-Components!$C$5)) -> 4.4626667 | T12: =IF(G12="","",ABS(O12-Components!$C$6)) -> 1.0556667 | U12: =IF(G12="","",ABS(O12-Components!$C$7)) -> 1.2743333 | V12: =IF(F12="","",IF(M12="OK","NONE",INDEX({"S1","S2","W1","W2","N1","N2"},MATCH(MIN(P12:U12),P12:U12,0)))) -> NONE | W12: =IF(G12="","",IF(V12=E12,1,0)) -> 1
A13: 11 | B13: 1 | C13: R3 | D13: OK | E13: NONE | F13: 9.88 | G13: =0.97+F13 -> 10.85 | I13: =VLOOKUP(C13,Recipes!$A$2:$N$4,10,FALSE()) -> 10.94 | J13: =VLOOKUP(C13,Recipes!$A$2:$N$4,12,FALSE()) -> 0.052703574 | K13: =I13-3*J13 -> 10.781889 | L13: =I13+3*J13 -> 11.098111 | M13: =IF(G13="","",IF(AND(G13>=K13,G13<=L13),"OK","NG")) -> OK | N13: =IF(M13="","",IF(M13=D13,1,0)) -> 1 | O13: =IF(G13="","",I13-G13) -> 0.09 | P13: =IF(G13="","",ABS(O13-Components!$C$2)) -> 2.6633333 | Q13: =IF(G13="","",ABS(O13-Components!$C$3)) -> 3.946 | R13: =IF(G13="","",ABS(O13-Components!$C$4)) -> 0.90333333 | S13: =IF(G13="","",ABS(O13-Components!$C$5)) -> 4.4726667 | T13: =IF(G13="","",ABS(O13-Components!$C$6)) -> 1.0656667 | U13: =IF(G13="","",ABS(O13-Components!$C$7)) -> 1.2843333 | V13: =IF(F13="","",IF(M13="OK","NONE",INDEX({"S1","S2","W1","W2","N1","N2"},MATCH(MIN(P13:U13),P13:U13,0)))) -> NONE | W13: =IF(G13="","",IF(V13=E13,1,0)) -> 1
A14: 12 | B14: 1 | C14: R3 | D14: OK | E14: NONE | F14: 9.91 | G14: =0.97+F14 -> 10.88 | I14: =VLOOKUP(C14,Recipes!$A$2:$N$4,10,FALSE()) -> 10.94 | J14: =VLOOKUP(C14,Recipes!$A$2:$N$4,12,FALSE()) -> 0.052703574 | K14: =I14-3*J14 -> 10.781889 | L14: =I14+3*J14 -> 11.098111 | M14: =IF(G14="","",IF(AND(G14>=K14,G14<=L14),"OK","NG")) -> OK | N14: =IF(M14="","",IF(M14=D14,1,0)) -> 1 | O14: =IF(G14="","",I14-G14) -> 0.06 | P14: =IF(G14="","",ABS(O14-Components!$C$2)) -> 2.6933333 | Q14: =IF(G14="","",ABS(O14-Components!$C$3)) -> 3.976 | R14: =IF(G14="","",ABS(O14-Components!$C$4)) -> 0.93333333 | S14: =IF(G14="","",ABS(O14-Components!$C$5)) -> 4.5026667 | T14: =IF(G14="","",ABS(O14-Components!$C$6)) -> 1.0956667 | U14: =IF(G14="","",ABS(O14-Components!$C$7)) -> 1.3143333 | V14: =IF(F14="","",IF(M14="OK","NONE",INDEX({"S1","S2","W1","W2","N1","N2"},MATCH(MIN(P14:U14),P14:U14,0)))) -> NONE | W14: =IF(G14="","",IF(V14=E14,1,0)) -> 1
... A122: 120 | B122: 4 | C122: R3 | D122: NG | E122: N2 | F122: 8.59 | G122: =0.97+F122 -> 9.56 | I122: =VLOOKUP(C122,Recipes!$A$2:$N$4,10,FALSE()) -> 10.94 | J122: =VLOOKUP(C122,Recipes!$A$2:$N$4,12,FALSE()) -> 0.052703574 | K122: =I122-3*J122 -> 10.781889 | L122: =I122+3*J122 -> 11.098111 | M122: =IF(G122="","",IF(AND(G122>=K122,G122<=L122),"OK","NG")) -> NG | N122: =IF(M122="","",IF(M122=D122,1,0)) -> 1 | O122: =IF(G122="","",I122-G122) -> 1.38 | P122: =IF(G122="","",ABS(O122-Components!$C$2)) -> 1.3733333 | Q122: =IF(G122="","",ABS(O122-Components!$C$3)) -> 2.656 | R122: =IF(G122="","",ABS(O122-Components!$C$4)) -> 0.38666667 | S122: =IF(G122="","",ABS(O122-Components!$C$5)) -> 3.1826667 | T122: =IF(G122="","",ABS(O122-Components!$C$6)) -> 0.22433333 | U122: =IF(G122="","",ABS(O122-Components!$C$7)) -> 0.0056666667 | V122: =IF(F122="","",IF(M122="OK","NONE",INDEX({"S1","S2","W1","W2","N1","N2"},MATCH(MIN(P122:U122),P122:U122,0)))) -> N2 | W122: =IF(G122="","",IF(V122=E122,1,0)) -> 1
A123: 121 | B123: 5 | C123: R4 | D123: OK | E123: NONE | F123: 8.95 | G123: =0.97+F123 -> 9.92 | I123: 9.91 | J123: =VLOOKUP(C123,Recipes!$A$2:$N$4,12,FALSE()) -> 0.050137397 | K123: =I123-3*J123 -> 9.7595878 | L123: =I123+3*J123 -> 10.060412 | M123: =IF(G123="","",IF(AND(G123>=K123,G123<=L123),"OK","NG")) -> OK | N123: =IF(M123="","",IF(M123=D123,1,0)) -> 1 | O123: =IF(G123="","",I123-G123) -> -0.01 | P123: =IF(G123="","",ABS(O123-Components!$C$2)) -> 2.7633333 | Q123: =IF(G123="","",ABS(O123-Components!$C$3)) -> 4.046 | R123: =IF(G123="","",ABS(O123-Components!$C$4)) -> 1.0033333 | S123: =IF(G123="","",ABS(O123-Components!$C$5)) -> 4.5726667 | T123: =IF(G123="","",ABS(O123-Components!$C$6)) -> 1.1656667 | U123: =IF(G123="","",ABS(O123-Components!$C$7)) -> 1.3843333 | V123: =IF(F123="","",IF(M123="OK","NONE",INDEX({"S1","S2","W1","W2","N1","N2"},MATCH(MIN(P123:U123),P123:U123,0)))) -> NONE | W123: =IF(G123="","",IF(V123=E123,1,0)) -> 1
A124: 122 | B124: 5 | C124: R4 | D124: OK | E124: NONE | F124: 8.94 | G124: =0.97+F124 -> 9.91 | I124: 9.91 | J124: =VLOOKUP(C124,Recipes!$A$2:$N$4,12,FALSE()) -> 0.050137397 | K124: =I124-3*J124 -> 9.7595878 | L124: =I124+3*J124 -> 10.060412 | M124: =IF(G124="","",IF(AND(G124>=K124,G124<=L124),"OK","NG")) -> OK | N124: =IF(M124="","",IF(M124=D124,1,0)) -> 1 | O124: =IF(G124="","",I124-G124) -> 0 | P124: =IF(G124="","",ABS(O124-Components!$C$2)) -> 2.7533333 | Q124: =IF(G124="","",ABS(O124-Components!$C$3)) -> 4.036 | R124: =IF(G124="","",ABS(O124-Components!$C$4)) -> 0.99333333 | S124: =IF(G124="","",ABS(O124-Components!$C$5)) -> 4.5626667 | T124: =IF(G124="","",ABS(O124-Components!$C$6)) -> 1.1556667 | U124: =IF(G124="","",ABS(O124-Components!$C$7)) -> 1.3743333 | V124: =IF(F124="","",IF(M124="OK","NONE",INDEX({"S1","S2","W1","W2","N1","N2"},MATCH(MIN(P124:U124),P124:U124,0)))) -> NONE | W124: =IF(G124="","",IF(V124=E124,1,0)) -> 1
A125: 123 | B125: 5 | C125: R4 | D125: OK | E125: NONE | F125: 8.94 | G125: =0.97+F125 -> 9.91 | I125: 9.91 | J125: =VLOOKUP(C125,Recipes!$A$2:$N$4,12,FALSE()) -> 0.050137397 | K125: =I125-3*J125 -> 9.7595878 | L125: =I125+3*J125 -> 10.060412 | M125: =IF(G125="","",IF(AND(G125>=K125,G125<=L125),"OK","NG")) -> OK | N125: =IF(M125="","",IF(M125=D125,1,0)) -> 1 | O125: =IF(G125="","",I125-G125) -> 0 | P125: =IF(G125="","",ABS(O125-Components!$C$2)) -> 2.7533333 | Q125: =IF(G125="","",ABS(O125-Components!$C$3)) -> 4.036 | R125: =IF(G125="","",ABS(O125-Components!$C$4)) -> 0.99333333 | S125: =IF(G125="","",ABS(O125-Components!$C$5)) -> 4.5626667 | T125: =IF(G125="","",ABS(O125-Components!$C$6)) -> 1.1556667 | U125: =IF(G125="","",ABS(O125-Components!$C$7)) -> 1.3743333 | V125: =IF(F125="","",IF(M125="OK","NONE",INDEX({"S1","S2","W1","W2","N1","N2"},MATCH(MIN(P125:U125),P125:U125,0)))) -> NONE | W125: =IF(G125="","",IF(V125=E125,1,0)) -> 1
A126: 124 | B126: 5 | C126: R4 | D126: OK | E126: NONE | F126: 8.89 | G126: =0.97+F126 -> 9.86 | I126: 9.91 | J126: =VLOOKUP(C126,Recipes!$A$2:$N$4,12,FALSE()) -> 0.050137397 | K126: =I126-3*J126 -> 9.7595878 | L126: =I126+3*J126 -> 10.060412 | M126: =IF(G126="","",IF(AND(G126>=K126,G126<=L126),"OK","NG")) -> OK | N126: =IF(M126="","",IF(M126=D126,1,0)) -> 1 | O126: =IF(G126="","",I126-G126) -> 0.05 | P126: =IF(G126="","",ABS(O126-Components!$C$2)) -> 2.7033333 | Q126: =IF(G126="","",ABS(O126-Components!$C$3)) -> 3.986 | R126: =IF(G126="","",ABS(O126-Components!$C$4)) -> 0.94333333 | S126: =IF(G126="","",ABS(O126-Components!$C$5)) -> 4.5126667 | T126: =IF(G126="","",ABS(O126-Components!$C$6)) -> 1.1056667 | U126: =IF(G126="","",ABS(O126-Components!$C$7)) -> 1.3243333 | V126: =IF(F126="","",IF(M126="OK","NONE",INDEX({"S1","S2","W1","W2","N1","N2"},MATCH(MIN(P126:U126),P126:U126,0)))) -> NONE | W126: =IF(G126="","",IF(V126=E126,1,0)) -> 1
A127: 125 | B127: 5 | C127: R4 | D127: OK | E127: NONE | F127: 8.89 | G127: =0.97+F127 -> 9.86 | I127: 9.91 | J127: =VLOOKUP(C127,Recipes!$A$2:$N$4,12,FALSE()) -> 0.050137397 | K127: =I127-3*J127 -> 9.7595878 | L127: =I127+3*J127 -> 10.060412 | M127: =IF(G127="","",IF(AND(G127>=K127,G127<=L127),"OK","NG")) -> OK | N127: =IF(M127="","",IF(M127=D127,1,0)) -> 1 | O127: =IF(G127="","",I127-G127) -> 0.05 | P127: =IF(G127="","",ABS(O127-Components!$C$2)) -> 2.7033333 | Q127: =IF(G127="","",ABS(O127-Components!$C$3)) -> 3.986 | R127: =IF(G127="","",ABS(O127-Components!$C$4)) -> 0.94333333 | S127: =IF(G127="","",ABS(O127-Components!$C$5)) -> 4.5126667 | T127: =IF(G127="","",ABS(O127-Components!$C$6)) -> 1.1056667 | U127: =IF(G127="","",ABS(O127-Components!$C$7)) -> 1.3243333 | V127: =IF(F127="","",IF(M127="OK","NONE",INDEX({"S1","S2","W1","W2","N1","N2"},MATCH(MIN(P127:U127),P127:U127,0)))) -> NONE | W127: =IF(G127="","",IF(V127=E127,1,0)) -> 1
A128: 126 | B128: 5 | C128: R4 | D128: OK | E128: NONE | F128: 8.88 | G128: =0.97+F128 -> 9.85 | I128: 9.91 | J128: =VLOOKUP(C128,Recipes!$A$2:$N$4,12,FALSE()) -> 0.050137397 | K128: =I128-3*J128 -> 9.7595878 | L128: =I128+3*J128 -> 10.060412 | M128: =IF(G128="","",IF(AND(G128>=K128,G128<=L128),"OK","NG")) -> OK | N128: =IF(M128="","",IF(M128=D128,1,0)) -> 1 | O128: =IF(G128="","",I128-G128) -> 0.06 | P128: =IF(G128="","",ABS(O128-Components!$C$2)) -> 2.6933333 | Q128: =IF(G128="","",ABS(O128-Components!$C$3)) -> 3.976 | R128: =IF(G128="","",ABS(O128-Components!$C$4)) -> 0.93333333 | S128: =IF(G128="","",ABS(O128-Components!$C$5)) -> 4.5026667 | T128: =IF(G128="","",ABS(O128-Components!$C$6)) -> 1.0956667 | U128: =IF(G128="","",ABS(O128-Components!$C$7)) -> 1.3143333 | V128: =IF(F128="","",IF(M128="OK","NONE",INDEX({"S1","S2","W1","W2","N1","N2"},MATCH(MIN(P128:U128),P128:U128,0)))) -> NONE | W128: =IF(G128="","",IF(V128=E128,1,0)) -> 1
A129: 127 | B129: 5 | C129: R4 | D129: OK | E129: NONE | F129: 8.91 | G129: =0.97+F129 -> 9.88 | I129: 9.91 | J129: =VLOOKUP(C129,Recipes!$A$2:$N$4,12,FALSE()) -> 0.050137397 | K129: =I129-3*J129 -> 9.7595878 | L129: =I129+3*J129 -> 10.060412 | M129: =IF(G129="","",IF(AND(G129>=K129,G129<=L129),"OK","NG")) -> OK | N129: =IF(M129="","",IF(M129=D129,1,0)) -> 1 | O129: =IF(G129="","",I129-G129) -> 0.03 | P129: =IF(G129="","",ABS(O129-Components!$C$2)) -> 2.7233333 | Q129: =IF(G129="","",ABS(O129-Components!$C$3)) -> 4.006 | R129: =IF(G129="","",ABS(O129-Components!$C$4)) -> 0.96333333 | S129: =IF(G129="","",ABS(O129-Components!$C$5)) -> 4.5326667 | T129: =IF(G129="","",ABS(O129-Components!$C$6)) -> 1.1256667 | U129: =IF(G129="","",ABS(O129-Components!$C$7)) -> 1.3443333 | V129: =IF(F129="","",IF(M129="OK","NONE",INDEX({"S1","S2","W1","W2","N1","N2"},MATCH(MIN(P129:U129),P129:U129,0)))) -> NONE | W129: =IF(G129="","",IF(V129=E129,1,0)) -> 1
A130: 128 | B130: 5 | C130: R4 | D130: OK | E130: NONE | F130: 8.85 | G130: =0.97+F130 -> 9.82 | I130: 9.91 | J130: =VLOOKUP(C130,Recipes!$A$2:$N$4,12,FALSE()) -> 0.050137397 | K130: =I130-3*J130 -> 9.7595878 | L130: =I130+3*J130 -> 10.060412 | M130: =IF(G130="","",IF(AND(G130>=K130,G130<=L130),"OK","NG")) -> OK | N130: =IF(M130="","",IF(M130=D130,1,0)) -> 1 | O130: =IF(G130="","",I130-G130) -> 0.09 | P130: =IF(G130="","",ABS(O130-Components!$C$2)) -> 2.6633333 | Q130: =IF(G130="","",ABS(O130-Components!$C$3)) -> 3.946 | R130: =IF(G130="","",ABS(O130-Components!$C$4)) -> 0.90333333 | S130: =IF(G130="","",ABS(O130-Components!$C$5)) -> 4.4726667 | T130: =IF(G130="","",ABS(O130-Components!$C$6)) -> 1.0656667 | U130: =IF(G130="","",ABS(O130-Components!$C$7)) -> 1.2843333 | V130: =IF(F130="","",IF(M130="OK","NONE",INDEX({"S1","S2","W1","W2","N1","N2"},MATCH(MIN(P130:U130),P130:U130,0)))) -> NONE | W130: =IF(G130="","",IF(V130=E130,1,0)) -> 1
A131: 129 | B131: 5 | C131: R4 | D131: OK | E131: NONE | F131: 8.88 | G131: =0.97+F131 -> 9.85 | I131: 9.91 | J131: =VLOOKUP(C131,Recipes!$A$2:$N$4,12,FALSE()) -> 0.050137397 | K131: =I131-3*J131 -> 9.7595878 | L131: =I131+3*J131 -> 10.060412 | M131: =IF(G131="","",IF(AND(G131>=K131,G131<=L131),"OK","NG")) -> OK | N131: =IF(M131="","",IF(M131=D131,1,0)) -> 1 | O131: =IF(G131="","",I131-G131) -> 0.06 | P131: =IF(G131="","",ABS(O131-Components!$C$2)) -> 2.6933333 | Q131: =IF(G131="","",ABS(O131-Components!$C$3)) -> 3.976 | R131: =IF(G131="","",ABS(O131-Components!$C$4)) -> 0.93333333 | S131: =IF(G131="","",ABS(O131-Components!$C$5)) -> 4.5026667 | T131: =IF(G131="","",ABS(O131-Components!$C$6)) -> 1.0956667 | U131: =IF(G131="","",ABS(O131-Components!$C$7)) -> 1.3143333 | V131: =IF(F131="","",IF(M131="OK","NONE",INDEX({"S1","S2","W1","W2","N1","N2"},MATCH(MIN(P131:U131),P131:U131,0)))) -> NONE | W131: =IF(G131="","",IF(V131=E131,1,0)) -> 1
A132: 130 | B132: 5 | C132: R4 | D132: OK | E132: NONE | F132: 8.87 | G132: =0.97+F132 -> 9.84 | I132: 9.91 | J132: =VLOOKUP(C132,Recipes!$A$2:$N$4,12,FALSE()) -> 0.050137397 | K132: =I132-3*J132 -> 9.7595878 | L132: =I132+3*J132 -> 10.060412 | M132: =IF(G132="","",IF(AND(G132>=K132,G132<=L132),"OK","NG")) -> OK | N132: =IF(M132="","",IF(M132=D132,1,0)) -> 1 | O132: =IF(G132="","",I132-G132) -> 0.07 | P132: =IF(G132="","",ABS(O132-Components!$C$2)) -> 2.6833333 | Q132: =IF(G132="","",ABS(O132-Components!$C$3)) -> 3.966 | R132: =IF(G132="","",ABS(O132-Components!$C$4)) -> 0.92333333 | S132: =IF(G132="","",ABS(O132-Components!$C$5)) -> 4.4926667 | T132: =IF(G132="","",ABS(O132-Components!$C$6)) -> 1.0856667 | U132: =IF(G132="","",ABS(O132-Components!$C$7)) -> 1.3043333 | V132: =IF(F132="","",IF(M132="OK","NONE",INDEX({"S1","S2","W1","W2","N1","N2"},MATCH(MIN(P132:U132),P132:U132,0)))) -> NONE | W132: =IF(G132="","",IF(V132=E132,1,0)) -> 1
A133: 131 | B133: 5 | C133: R4 | D133: OK | E133: NONE | F133: 8.89 | G133: =0.97+F133 -> 9.86 | I133: 9.91 | J133: =VLOOKUP(C133,Recipes!$A$2:$N$4,12,FALSE()) -> 0.050137397 | K133: =I133-3*J133 -> 9.7595878 | L133: =I133+3*J133 -> 10.060412 | M133: =IF(G133="","",IF(AND(G133>=K133,G133<=L133),"OK","NG")) -> OK | N133: =IF(M133="","",IF(M133=D133,1,0)) -> 1 | O133: =IF(G133="","",I133-G133) -> 0.05 | P133: =IF(G133="","",ABS(O133-Components!$C$2)) -> 2.7033333 | Q133: =IF(G133="","",ABS(O133-Components!$C$3)) -> 3.986 | R133: =IF(G133="","",ABS(O133-Components!$C$4)) -> 0.94333333 | S133: =IF(G133="","",ABS(O133-Components!$C$5)) -> 4.5126667 | T133: =IF(G133="","",ABS(O133-Components!$C$6)) -> 1.1056667 | U133: =IF(G133="","",ABS(O133-Components!$C$7)) -> 1.3243333 | V133: =IF(F133="","",IF(M133="OK","NONE",INDEX({"S1","S2","W1","W2","N1","N2"},MATCH(MIN(P133:U133),P133:U133,0)))) -> NONE | W133: =IF(G133="","",IF(V133=E133,1,0)) -> 1
A134: 132 | B134: 5 | C134: R4 | D134: OK | E134: NONE | F134: 8.87 | G134: =0.97+F134 -> 9.84 | I134: 9.91 | J134: =VLOOKUP(C134,Recipes!$A$2:$N$4,12,FALSE()) -> 0.050137397 | K134: =I134-3*J134 -> 9.7595878 | L134: =I134+3*J134 -> 10.060412 | M134: =IF(G134="","",IF(AND(G134>=K134,G134<=L134),"OK","NG")) -> OK | N134: =IF(M134="","",IF(M134=D134,1,0)) -> 1 | O134: =IF(G134="","",I134-G134) -> 0.07 | P134: =IF(G134="","",ABS(O134-Components!$C$2)) -> 2.6833333 | Q134: =IF(G134="","",ABS(O134-Components!$C$3)) -> 3.966 | R134: =IF(G134="","",ABS(O134-Components!$C$4)) -> 0.92333333 | S134: =IF(G134="","",ABS(O134-Components!$C$5)) -> 4.4926667 | T134: =IF(G134="","",ABS(O134-Components!$C$6)) -> 1.0856667 | U134: =IF(G134="","",ABS(O134-Components!$C$7)) -> 1.3043333 | V134: =IF(F134="","",IF(M134="OK","NONE",INDEX({"S1","S2","W1","W2","N1","N2"},MATCH(MIN(P134:U134),P134:U134,0)))) -> NONE | W134: =IF(G134="","",IF(V134=E134,1,0)) -> 1
... A422: 420 | B422: 14 | C422: R6 | D422: NG | E422: N1 | F422: 7.47 | G422: =0.97+F422 -> 8.44 | I422: 9.61 | J422: =VLOOKUP(C422,Recipes!$A$2:$N$4,12,FALSE()) -> 0.061509461 | K422: =I422-3*J422 -> 9.4254716 | L422: =I422+3*J422 -> 9.7945284 | M422: =IF(G422="","",IF(AND(G422>=K422,G422<=L422),"OK","NG")) -> NG | N422: =IF(M422="","",IF(M422=D422,1,0)) -> 1 | O422: =IF(G422="","",I422-G422) -> 1.17 | P422: =IF(G422="","",ABS(O422-Components!$C$2)) -> 1.5833333 | Q422: =IF(G422="","",ABS(O422-Components!$C$3)) -> 2.866 | R422: =IF(G422="","",ABS(O422-Components!$C$4)) -> 0.17666667 | S422: =IF(G422="","",ABS(O422-Components!$C$5)) -> 3.3926667 | T422: =IF(G422="","",ABS(O422-Components!$C$6)) -> 0.014333333 | U422: =IF(G422="","",ABS(O422-Components!$C$7)) -> 0.20433333 | V422: =IF(F422="","",IF(M422="OK","NONE",INDEX({"S1","S2","W1","W2","N1","N2"},MATCH(MIN(P422:U422),P422:U422,0)))) -> N1 | W422: =IF(G422="","",IF(V422=E422,1,0)) -> 1

Sheet Runs Distance 2 + 3 S 20262904
A2: run_id | B2: execution_order | C2: recipe | D2: condition | E2: missing_component | F2: kit_id | G2: measured_weight_g | H2: timestamp | I2: notes | J2: expected_weight | K2: expected_std | L2: lower_bound | M2: upper_bound | N2: predicted_OK_NG | O2: L1_correct | P2: deficit | Q2: match_S1 | R2: match_S2 | S2: match_W1 | T2: match_W2 | U2: match_N1 | V2: match_N2 | W2: predicted_missing | X2: L2_correct
A3: 1 | B3: 31 | C3: R3 | D3: OK | E3: NONE | F3: K001 | G3: 9.91 | J3: =VLOOKUP(C3,Recipes!$A$2:$N$4,10,FALSE()) -> 10.94 | K3: =VLOOKUP(C3,Recipes!$A$2:$N$4,12,FALSE()) -> 0.052703574 | L3: =J3-3*K3 -> 10.781889 | M3: =J3+3*K3 -> 11.098111 | N3: =IF(G3="","",IF(AND(G3>=L3,G3<=M3),"OK","NG")) -> NG | O3: =IF(N3="","",IF(N3=D3,1,0)) -> 0 | P3: =IF(G3="","",J3-G3) -> 1.03 | Q3: =IF(G3="","",ABS(P3-Components!$C$2)) -> 1.7233333 | R3: =IF(G3="","",ABS(P3-Components!$C$3)) -> 3.006 | S3: =IF(G3="","",ABS(P3-Components!$C$4)) -> 0.036666667 | T3: =IF(G3="","",ABS(P3-Components!$C$5)) -> 3.5326667 | U3: =IF(G3="","",ABS(P3-Components!$C$6)) -> 0.12566667 | V3: =IF(G3="","",ABS(P3-Components!$C$7)) -> 0.34433333 | W3: =IF(G3="","",IF(N3="OK","NONE",INDEX({"S1","S2","W1","W2","N1","N2"},MATCH(MIN(Q3:V3),Q3:V3,0)))) -> W1 | X3: =IF(G3="","",IF(W3=E3,1,0)) -> 0
A4: 2 | B4: 24 | C4: R3 | D4: OK | E4: NONE | F4: K002 | G4: 10 | J4: =VLOOKUP(C4,Recipes!$A$2:$N$4,10,FALSE()) -> 10.94 | K4: =VLOOKUP(C4,Recipes!$A$2:$N$4,12,FALSE()) -> 0.052703574 | L4: =J4-3*K4 -> 10.781889 | M4: =J4+3*K4 -> 11.098111 | N4: =IF(G4="","",IF(AND(G4>=L4,G4<=M4),"OK","NG")) -> NG | O4: =IF(N4="","",IF(N4=D4,1,0)) -> 0 | P4: =IF(G4="","",J4-G4) -> 0.94 | Q4: =IF(G4="","",ABS(P4-Components!$C$2)) -> 1.8133333 | R4: =IF(G4="","",ABS(P4-Components!$C$3)) -> 3.096 | S4: =IF(G4="","",ABS(P4-Components!$C$4)) -> 0.053333333 | T4: =IF(G4="","",ABS(P4-Components!$C$5)) -> 3.6226667 | U4: =IF(G4="","",ABS(P4-Components!$C$6)) -> 0.21566667 | V4: =IF(G4="","",ABS(P4-Components!$C$7)) -> 0.43433333 | W4: =IF(G4="","",IF(N4="OK","NONE",INDEX({"S1","S2","W1","W2","N1","N2"},MATCH(MIN(Q4:V4),Q4:V4,0)))) -> W1 | X4: =IF(G4="","",IF(W4=E4,1,0)) -> 0
A5: 3 | B5: 50 | C5: R3 | D5: OK | E5: NONE | F5: K003 | G5: 10 | J5: =VLOOKUP(C5,Recipes!$A$2:$N$4,10,FALSE()) -> 10.94 | K5: =VLOOKUP(C5,Recipes!$A$2:$N$4,12,FALSE()) -> 0.052703574 | L5: =J5-3*K5 -> 10.781889 | M5: =J5+3*K5 -> 11.098111 | N5: =IF(G5="","",IF(AND(G5>=L5,G5<=M5),"OK","NG")) -> NG | O5: =IF(N5="","",IF(N5=D5,1,0)) -> 0 | P5: =IF(G5="","",J5-G5) -> 0.94 | Q5: =IF(G5="","",ABS(P5-Components!$C$2)) -> 1.8133333 | R5: =IF(G5="","",ABS(P5-Components!$C$3)) -> 3.096 | S5: =IF(G5="","",ABS(P5-Components!$C$4)) -> 0.053333333 | T5: =IF(G5="","",ABS(P5-Components!$C$5)) -> 3.6226667 | U5: =IF(G5="","",ABS(P5-Components!$C$6)) -> 0.21566667 | V5: =IF(G5="","",ABS(P5-Components!$C$7)) -> 0.43433333 | W5: =IF(G5="","",IF(N5="OK","NONE",INDEX({"S1","S2","W1","W2","N1","N2"},MATCH(MIN(Q5:V5),Q5:V5,0)))) -> W1 | X5: =IF(G5="","",IF(W5=E5,1,0)) -> 0
A6: 4 | B6: 12 | C6: R3 | D6: OK | E6: NONE | F6: K004 | G6: 9.91 | J6: =VLOOKUP(C6,Recipes!$A$2:$N$4,10,FALSE()) -> 10.94 | K6: =VLOOKUP(C6,Recipes!$A$2:$N$4,12,FALSE()) -> 0.052703574 | L6: =J6-3*K6 -> 10.781889 | M6: =J6+3*K6 -> 11.098111 | N6: =IF(G6="","",IF(AND(G6>=L6,G6<=M6),"OK","NG")) -> NG | O6: =IF(N6="","",IF(N6=D6,1,0)) -> 0 | P6: =IF(G6="","",J6-G6) -> 1.03 | Q6: =IF(G6="","",ABS(P6-Components!$C$2)) -> 1.7233333 | R6: =IF(G6="","",ABS(P6-Components!$C$3)) -> 3.006 | S6: =IF(G6="","",ABS(P6-Components!$C$4)) -> 0.036666667 | T6: =IF(G6="","",ABS(P6-Components!$C$5)) -> 3.5326667 | U6: =IF(G6="","",ABS(P6-Components!$C$6)) -> 0.12566667 | V6: =IF(G6="","",ABS(P6-Components!$C$7)) -> 0.34433333 | W6: =IF(G6="","",IF(N6="OK","NONE",INDEX({"S1","S2","W1","W2","N1","N2"},MATCH(MIN(Q6:V6),Q6:V6,0)))) -> W1 | X6: =IF(G6="","",IF(W6=E6,1,0)) -> 0
A7: 5 | B7: 17 | C7: R3 | D7: OK | E7: NONE | F7: K005 | G7: 10.04 | J7: =VLOOKUP(C7,Recipes!$A$2:$N$4,10,FALSE()) -> 10.94 | K7: =VLOOKUP(C7,Recipes!$A$2:$N$4,12,FALSE()) -> 0.052703574 | L7: =J7-3*K7 -> 10.781889 | M7: =J7+3*K7 -> 11.098111 | N7: =IF(G7="","",IF(AND(G7>=L7,G7<=M7),"OK","NG")) -> NG | O7: =IF(N7="","",IF(N7=D7,1,0)) -> 0 | P7: =IF(G7="","",J7-G7) -> 0.9 | Q7: =IF(G7="","",ABS(P7-Components!$C$2)) -> 1.8533333 | R7: =IF(G7="","",ABS(P7-Components!$C$3)) -> 3.136 | S7: =IF(G7="","",ABS(P7-Components!$C$4)) -> 0.093333333 | T7: =IF(G7="","",ABS(P7-Components!$C$5)) -> 3.6626667 | U7: =IF(G7="","",ABS(P7-Components!$C$6)) -> 0.25566667 | V7: =IF(G7="","",ABS(P7-Components!$C$7)) -> 0.47433333 | W7: =IF(G7="","",IF(N7="OK","NONE",INDEX({"S1","S2","W1","W2","N1","N2"},MATCH(MIN(Q7:V7),Q7:V7,0)))) -> W1 | X7: =IF(G7="","",IF(W7=E7,1,0)) -> 0
A8: 6 | B8: 17 | C8: R3 | D8: OK | E8: NONE | F8: K005 | G8: 9.84 | J8: =VLOOKUP(C8,Recipes!$A$2:$N$4,10,FALSE()) -> 10.94 | K8: =VLOOKUP(C8,Recipes!$A$2:$N$4,12,FALSE()) -> 0.052703574 | L8: =J8-3*K8 -> 10.781889 | M8: =J8+3*K8 -> 11.098111 | N8: =IF(G8="","",IF(AND(G8>=L8,G8<=M8),"OK","NG")) -> NG | O8: =IF(N8="","",IF(N8=D8,1,0)) -> 0 | P8: =IF(G8="","",J8-G8) -> 1.1 | Q8: =IF(G8="","",ABS(P8-Components!$C$2)) -> 1.6533333 | R8: =IF(G8="","",ABS(P8-Components!$C$3)) -> 2.936 | S8: =IF(G8="","",ABS(P8-Components!$C$4)) -> 0.10666667 | T8: =IF(G8="","",ABS(P8-Components!$C$5)) -> 3.4626667 | U8: =IF(G8="","",ABS(P8-Components!$C$6)) -> 0.055666667 | V8: =IF(G8="","",ABS(P8-Components!$C$7)) -> 0.27433333 | W8: =IF(G8="","",IF(N8="OK","NONE",INDEX({"S1","S2","W1","W2","N1","N2"},MATCH(MIN(Q8:V8),Q8:V8,0)))) -> N1 | X8: =IF(G8="","",IF(W8=E8,1,0)) -> 0
A9: 7 | B9: 17 | C9: R3 | D9: OK | E9: NONE | F9: K005 | G9: 9.9 | J9: =VLOOKUP(C9,Recipes!$A$2:$N$4,10,FALSE()) -> 10.94 | K9: =VLOOKUP(C9,Recipes!$A$2:$N$4,12,FALSE()) -> 0.052703574 | L9: =J9-3*K9 -> 10.781889 | M9: =J9+3*K9 -> 11.098111 | N9: =IF(G9="","",IF(AND(G9>=L9,G9<=M9),"OK","NG")) -> NG | O9: =IF(N9="","",IF(N9=D9,1,0)) -> 0 | P9: =IF(G9="","",J9-G9) -> 1.04 | Q9: =IF(G9="","",ABS(P9-Components!$C$2)) -> 1.7133333 | R9: =IF(G9="","",ABS(P9-Components!$C$3)) -> 2.996 | S9: =IF(G9="","",ABS(P9-Components!$C$4)) -> 0.046666667 | T9: =IF(G9="","",ABS(P9-Components!$C$5)) -> 3.5226667 | U9: =IF(G9="","",ABS(P9-Components!$C$6)) -> 0.11566667 | V9: =IF(G9="","",ABS(P9-Components!$C$7)) -> 0.33433333 | W9: =IF(G9="","",IF(N9="OK","NONE",INDEX({"S1","S2","W1","W2","N1","N2"},MATCH(MIN(Q9:V9),Q9:V9,0)))) -> W1 | X9: =IF(G9="","",IF(W9=E9,1,0)) -> 0
A10: 8 | B10: 17 | C10: R3 | D10: OK | E10: NONE | F10: K005 | G10: 9.92 | J10: =VLOOKUP(C10,Recipes!$A$2:$N$4,10,FALSE()) -> 10.94 | K10: =VLOOKUP(C10,Recipes!$A$2:$N$4,12,FALSE()) -> 0.052703574 | L10: =J10-3*K10 -> 10.781889 | M10: =J10+3*K10 -> 11.098111 | N10: =IF(G10="","",IF(AND(G10>=L10,G10<=M10),"OK","NG")) -> NG | O10: =IF(N10="","",IF(N10=D10,1,0)) -> 0 | P10: =IF(G10="","",J10-G10) -> 1.02 | Q10: =IF(G10="","",ABS(P10-Components!$C$2)) -> 1.7333333 | R10: =IF(G10="","",ABS(P10-Components!$C$3)) -> 3.016 | S10: =IF(G10="","",ABS(P10-Components!$C$4)) -> 0.026666667 | T10: =IF(G10="","",ABS(P10-Components!$C$5)) -> 3.5426667 | U10: =IF(G10="","",ABS(P10-Components!$C$6)) -> 0.13566667 | V10: =IF(G10="","",ABS(P10-Components!$C$7)) -> 0.35433333 | W10: =IF(G10="","",IF(N10="OK","NONE",INDEX({"S1","S2","W1","W2","N1","N2"},MATCH(MIN(Q10:V10),Q10:V10,0)))) -> W1 | X10: =IF(G10="","",IF(W10=E10,1,0)) -> 0
A11: 9 | B11: 17 | C11: R3 | D11: OK | E11: NONE | F11: K005 | G11: 9.95 | J11: =VLOOKUP(C11,Recipes!$A$2:$N$4,10,FALSE()) -> 10.94 | K11: =VLOOKUP(C11,Recipes!$A$2:$N$4,12,FALSE()) -> 0.052703574 | L11: =J11-3*K11 -> 10.781889 | M11: =J11+3*K11 -> 11.098111 | N11: =IF(G11="","",IF(AND(G11>=L11,G11<=M11),"OK","NG")) -> NG | O11: =IF(N11="","",IF(N11=D11,1,0)) -> 0 | P11: =IF(G11="","",J11-G11) -> 0.99 | Q11: =IF(G11="","",ABS(P11-Components!$C$2)) -> 1.7633333 | R11: =IF(G11="","",ABS(P11-Components!$C$3)) -> 3.046 | S11: =IF(G11="","",ABS(P11-Components!$C$4)) -> 0.0033333333 | T11: =IF(G11="","",ABS(P11-Components!$C$5)) -> 3.5726667 | U11: =IF(G11="","",ABS(P11-Components!$C$6)) -> 0.16566667 | V11: =IF(G11="","",ABS(P11-Components!$C$7)) -> 0.38433333 | W11: =IF(G11="","",IF(N11="OK","NONE",INDEX({"S1","S2","W1","W2","N1","N2"},MATCH(MIN(Q11:V11),Q11:V11,0)))) -> W1 | X11: =IF(G11="","",IF(W11=E11,1,0)) -> 0
A12: 10 | B12: 17 | C12: R3 | D12: OK | E12: NONE | F12: K005 | G12: 9.87 | J12: =VLOOKUP(C12,Recipes!$A$2:$N$4,10,FALSE()) -> 10.94 | K12: =VLOOKUP(C12,Recipes!$A$2:$N$4,12,FALSE()) -> 0.052703574 | L12: =J12-3*K12 -> 10.781889 | M12: =J12+3*K12 -> 11.098111 | N12: =IF(G12="","",IF(AND(G12>=L12,G12<=M12),"OK","NG")) -> NG | O12: =IF(N12="","",IF(N12=D12,1,0)) -> 0 | P12: =IF(G12="","",J12-G12) -> 1.07 | Q12: =IF(G12="","",ABS(P12-Components!$C$2)) -> 1.6833333 | R12: =IF(G12="","",ABS(P12-Components!$C$3)) -> 2.966 | S12: =IF(G12="","",ABS(P12-Components!$C$4)) -> 0.076666667 | T12: =IF(G12="","",ABS(P12-Components!$C$5)) -> 3.4926667 | U12: =IF(G12="","",ABS(P12-Components!$C$6)) -> 0.085666667 | V12: =IF(G12="","",ABS(P12-Components!$C$7)) -> 0.30433333 | W12: =IF(G12="","",IF(N12="OK","NONE",INDEX({"S1","S2","W1","W2","N1","N2"},MATCH(MIN(Q12:V12),Q12:V12,0)))) -> W1 | X12: =IF(G12="","",IF(W12=E12,1,0)) -> 0
A13: 11 | B13: 17 | C13: R3 | D13: OK | E13: NONE | F13: K005 | G13: 9.88 | J13: =VLOOKUP(C13,Recipes!$A$2:$N$4,10,FALSE()) -> 10.94 | K13: =VLOOKUP(C13,Recipes!$A$2:$N$4,12,FALSE()) -> 0.052703574 | L13: =J13-3*K13 -> 10.781889 | M13: =J13+3*K13 -> 11.098111 | N13: =IF(G13="","",IF(AND(G13>=L13,G13<=M13),"OK","NG")) -> NG | O13: =IF(N13="","",IF(N13=D13,1,0)) -> 0 | P13: =IF(G13="","",J13-G13) -> 1.06 | Q13: =IF(G13="","",ABS(P13-Components!$C$2)) -> 1.6933333 | R13: =IF(G13="","",ABS(P13-Components!$C$3)) -> 2.976 | S13: =IF(G13="","",ABS(P13-Components!$C$4)) -> 0.066666667 | T13: =IF(G13="","",ABS(P13-Components!$C$5)) -> 3.5026667 | U13: =IF(G13="","",ABS(P13-Components!$C$6)) -> 0.095666667 | V13: =IF(G13="","",ABS(P13-Components!$C$7)) -> 0.31433333 | W13: =IF(G13="","",IF(N13="OK","NONE",INDEX({"S1","S2","W1","W2","N1","N2"},MATCH(MIN(Q13:V13),Q13:V13,0)))) -> W1 | X13: =IF(G13="","",IF(W13=E13,1,0)) -> 0
A14: 12 | B14: 17 | C14: R3 | D14: OK | E14: NONE | F14: K005 | G14: 9.91 | J14: =VLOOKUP(C14,Recipes!$A$2:$N$4,10,FALSE()) -> 10.94 | K14: =VLOOKUP(C14,Recipes!$A$2:$N$4,12,FALSE()) -> 0.052703574 | L14: =J14-3*K14 -> 10.781889 | M14: =J14+3*K14 -> 11.098111 | N14: =IF(G14="","",IF(AND(G14>=L14,G14<=M14),"OK","NG")) -> NG | O14: =IF(N14="","",IF(N14=D14,1,0)) -> 0 | P14: =IF(G14="","",J14-G14) -> 1.03 | Q14: =IF(G14="","",ABS(P14-Components!$C$2)) -> 1.7233333 | R14: =IF(G14="","",ABS(P14-Components!$C$3)) -> 3.006 | S14: =IF(G14="","",ABS(P14-Components!$C$4)) -> 0.036666667 | T14: =IF(G14="","",ABS(P14-Components!$C$5)) -> 3.5326667 | U14: =IF(G14="","",ABS(P14-Components!$C$6)) -> 0.12566667 | V14: =IF(G14="","",ABS(P14-Components!$C$7)) -> 0.34433333 | W14: =IF(G14="","",IF(N14="OK","NONE",INDEX({"S1","S2","W1","W2","N1","N2"},MATCH(MIN(Q14:V14),Q14:V14,0)))) -> W1 | X14: =IF(G14="","",IF(W14=E14,1,0)) -> 0
... A115: 113 | B115: 47 | C115: R3 | D115: NG | E115: N2 | F115: K019 | G115: 8.59 | J115: =VLOOKUP(C115,Recipes!$A$2:$N$4,10,FALSE()) -> 10.94 | K115: =VLOOKUP(C115,Recipes!$A$2:$N$4,12,FALSE()) -> 0.052703574 | L115: =J115-3*K115 -> 10.781889 | M115: =J115+3*K115 -> 11.098111 | N115: =IF(G115="","",IF(AND(G115>=L115,G115<=M115),"OK","NG")) -> NG | O115: =IF(N115="","",IF(N115=D115,1,0)) -> 1 | P115: =IF(G115="","",J115-G115) -> 2.35 | Q115: =IF(G115="","",ABS(P115-Components!$C$2)) -> 0.40333333 | R115: =IF(G115="","",ABS(P115-Components!$C$3)) -> 1.686 | S115: =IF(G115="","",ABS(P115-Components!$C$4)) -> 1.3566667 | T115: =IF(G115="","",ABS(P115-Components!$C$5)) -> 2.2126667 | U115: =IF(G115="","",ABS(P115-Components!$C$6)) -> 1.1943333 | V115: =IF(G115="","",ABS(P115-Components!$C$7)) -> 0.97566667 | W115: =IF(G115="","",IF(N115="OK","NONE",INDEX({"S1","S2","W1","W2","N1","N2"},MATCH(MIN(Q115:V115),Q115:V115,0)))) -> S1 | X115: =IF(G115="","",IF(W115=E115,1,0)) -> 0
A116: 114 | B116: 47 | C116: R3 | D116: NG | E116: N2 | F116: K019 | J116: =VLOOKUP(C116,Recipes!$A$2:$N$4,10,FALSE()) -> 10.94 | K116: =VLOOKUP(C116,Recipes!$A$2:$N$4,12,FALSE()) -> 0.052703574 | L116: =J116-3*K116 -> 10.781889 | M116: =J116+3*K116 -> 11.098111 | N116: =IF(G116="","",IF(AND(G116>=L116,G116<=M116),"OK","NG")) | O116: =IF(N116="","",IF(N116=D116,1,0)) | P116: =IF(G116="","",J116-G116) | Q116: =IF(G116="","",ABS(P116-Components!$C$2)) | R116: =IF(G116="","",ABS(P116-Components!$C$3)) | S116: =IF(G116="","",ABS(P116-Components!$C$4)) | T116: =IF(G116="","",ABS(P116-Components!$C$5)) | U116: =IF(G116="","",ABS(P116-Components!$C$6)) | V116: =IF(G116="","",ABS(P116-Components!$C$7)) | W116: =IF(G116="","",IF(N116="OK","NONE",INDEX({"S1","S2","W1","W2","N1","N2"},MATCH(MIN(Q116:V116),Q116:V116,0)))) | X116: =IF(G116="","",IF(W116=E116,1,0))
A117: 115 | B117: 47 | C117: R3 | D117: NG | E117: N2 | F117: K019 | J117: =VLOOKUP(C117,Recipes!$A$2:$N$4,10,FALSE()) -> 10.94 | K117: =VLOOKUP(C117,Recipes!$A$2:$N$4,12,FALSE()) -> 0.052703574 | L117: =J117-3*K117 -> 10.781889 | M117: =J117+3*K117 -> 11.098111 | N117: =IF(G117="","",IF(AND(G117>=L117,G117<=M117),"OK","NG")) | O117: =IF(N117="","",IF(N117=D117,1,0)) | P117: =IF(G117="","",J117-G117) | Q117: =IF(G117="","",ABS(P117-Components!$C$2)) | R117: =IF(G117="","",ABS(P117-Components!$C$3)) | S117: =IF(G117="","",ABS(P117-Components!$C$4)) | T117: =IF(G117="","",ABS(P117-Components!$C$5)) | U117: =IF(G117="","",ABS(P117-Components!$C$6)) | V117: =IF(G117="","",ABS(P117-Components!$C$7)) | W117: =IF(G117="","",IF(N117="OK","NONE",INDEX({"S1","S2","W1","W2","N1","N2"},MATCH(MIN(Q117:V117),Q117:V117,0)))) | X117: =IF(G117="","",IF(W117=E117,1,0))
A118: 116 | B118: 47 | C118: R3 | D118: NG | E118: N2 | F118: K019 | J118: =VLOOKUP(C118,Recipes!$A$2:$N$4,10,FALSE()) -> 10.94 | K118: =VLOOKUP(C118,Recipes!$A$2:$N$4,12,FALSE()) -> 0.052703574 | L118: =J118-3*K118 -> 10.781889 | M118: =J118+3*K118 -> 11.098111 | N118: =IF(G118="","",IF(AND(G118>=L118,G118<=M118),"OK","NG")) | O118: =IF(N118="","",IF(N118=D118,1,0)) | P118: =IF(G118="","",J118-G118) | Q118: =IF(G118="","",ABS(P118-Components!$C$2)) | R118: =IF(G118="","",ABS(P118-Components!$C$3)) | S118: =IF(G118="","",ABS(P118-Components!$C$4)) | T118: =IF(G118="","",ABS(P118-Components!$C$5)) | U118: =IF(G118="","",ABS(P118-Components!$C$6)) | V118: =IF(G118="","",ABS(P118-Components!$C$7)) | W118: =IF(G118="","",IF(N118="OK","NONE",INDEX({"S1","S2","W1","W2","N1","N2"},MATCH(MIN(Q118:V118),Q118:V118,0)))) | X118: =IF(G118="","",IF(W118=E118,1,0))
A119: 117 | B119: 47 | C119: R3 | D119: NG | E119: N2 | F119: K019 | J119: =VLOOKUP(C119,Recipes!$A$2:$N$4,10,FALSE()) -> 10.94 | K119: =VLOOKUP(C119,Recipes!$A$2:$N$4,12,FALSE()) -> 0.052703574 | L119: =J119-3*K119 -> 10.781889 | M119: =J119+3*K119 -> 11.098111 | N119: =IF(G119="","",IF(AND(G119>=L119,G119<=M119),"OK","NG")) | O119: =IF(N119="","",IF(N119=D119,1,0)) | P119: =IF(G119="","",J119-G119) | Q119: =IF(G119="","",ABS(P119-Components!$C$2)) | R119: =IF(G119="","",ABS(P119-Components!$C$3)) | S119: =IF(G119="","",ABS(P119-Components!$C$4)) | T119: =IF(G119="","",ABS(P119-Components!$C$5)) | U119: =IF(G119="","",ABS(P119-Components!$C$6)) | V119: =IF(G119="","",ABS(P119-Components!$C$7)) | W119: =IF(G119="","",IF(N119="OK","NONE",INDEX({"S1","S2","W1","W2","N1","N2"},MATCH(MIN(Q119:V119),Q119:V119,0)))) | X119: =IF(G119="","",IF(W119=E119,1,0))
A120: 118 | B120: 47 | C120: R3 | D120: NG | E120: N2 | F120: K019 | J120: =VLOOKUP(C120,Recipes!$A$2:$N$4,10,FALSE()) -> 10.94 | K120: =VLOOKUP(C120,Recipes!$A$2:$N$4,12,FALSE()) -> 0.052703574 | L120: =J120-3*K120 -> 10.781889 | M120: =J120+3*K120 -> 11.098111 | N120: =IF(G120="","",IF(AND(G120>=L120,G120<=M120),"OK","NG")) | O120: =IF(N120="","",IF(N120=D120,1,0)) | P120: =IF(G120="","",J120-G120) | Q120: =IF(G120="","",ABS(P120-Components!$C$2)) | R120: =IF(G120="","",ABS(P120-Components!$C$3)) | S120: =IF(G120="","",ABS(P120-Components!$C$4)) | T120: =IF(G120="","",ABS(P120-Components!$C$5)) | U120: =IF(G120="","",ABS(P120-Components!$C$6)) | V120: =IF(G120="","",ABS(P120-Components!$C$7)) | W120: =IF(G120="","",IF(N120="OK","NONE",INDEX({"S1","S2","W1","W2","N1","N2"},MATCH(MIN(Q120:V120),Q120:V120,0)))) | X120: =IF(G120="","",IF(W120=E120,1,0))
A121: 119 | B121: 47 | C121: R3 | D121: NG | E121: N2 | F121: K019 | J121: =VLOOKUP(C121,Recipes!$A$2:$N$4,10,FALSE()) -> 10.94 | K121: =VLOOKUP(C121,Recipes!$A$2:$N$4,12,FALSE()) -> 0.052703574 | L121: =J121-3*K121 -> 10.781889 | M121: =J121+3*K121 -> 11.098111 | N121: =IF(G121="","",IF(AND(G121>=L121,G121<=M121),"OK","NG")) | O121: =IF(N121="","",IF(N121=D121,1,0)) | P121: =IF(G121="","",J121-G121) | Q121: =IF(G121="","",ABS(P121-Components!$C$2)) | R121: =IF(G121="","",ABS(P121-Components!$C$3)) | S121: =IF(G121="","",ABS(P121-Components!$C$4)) | T121: =IF(G121="","",ABS(P121-Components!$C$5)) | U121: =IF(G121="","",ABS(P121-Components!$C$6)) | V121: =IF(G121="","",ABS(P121-Components!$C$7)) | W121: =IF(G121="","",IF(N121="OK","NONE",INDEX({"S1","S2","W1","W2","N1","N2"},MATCH(MIN(Q121:V121),Q121:V121,0)))) | X121: =IF(G121="","",IF(W121=E121,1,0))
A122: 120 | B122: 47 | C122: R3 | D122: NG | E122: N2 | F122: K019 | G122: 8.56 | J122: =VLOOKUP(C122,Recipes!$A$2:$N$4,10,FALSE()) -> 10.94 | K122: =VLOOKUP(C122,Recipes!$A$2:$N$4,12,FALSE()) -> 0.052703574 | L122: =J122-3*K122 -> 10.781889 | M122: =J122+3*K122 -> 11.098111 | N122: =IF(G122="","",IF(AND(G122>=L122,G122<=M122),"OK","NG")) -> NG | O122: =IF(N122="","",IF(N122=D122,1,0)) -> 1 | P122: =IF(G122="","",J122-G122) -> 2.38 | Q122: =IF(G122="","",ABS(P122-Components!$C$2)) -> 0.37333333 | R122: =IF(G122="","",ABS(P122-Components!$C$3)) -> 1.656 | S122: =IF(G122="","",ABS(P122-Components!$C$4)) -> 1.3866667 | T122: =IF(G122="","",ABS(P122-Components!$C$5)) -> 2.1826667 | U122: =IF(G122="","",ABS(P122-Components!$C$6)) -> 1.2243333 | V122: =IF(G122="","",ABS(P122-Components!$C$7)) -> 1.0056667 | W122: =IF(G122="","",IF(N122="OK","NONE",INDEX({"S1","S2","W1","W2","N1","N2"},MATCH(MIN(Q122:V122),Q122:V122,0)))) -> S1 | X122: =IF(G122="","",IF(W122=E122,1,0)) -> 0
A123: 121 | B123: 29 | C123: R4 | D123: OK | E123: NONE | F123: K021 | G123: 8.95 | J123: =VLOOKUP(C123,Recipes!$A$2:$N$4,10,FALSE()) -> 9.9053333 | K123: =VLOOKUP(C123,Recipes!$A$2:$N$4,12,FALSE()) -> 0.050137397 | L123: =J123-3*K123 -> 9.7549211 | M123: =J123+3*K123 -> 10.055746 | N123: =IF(G123="","",IF(AND(G123>=L123,G123<=M123),"OK","NG")) -> NG | O123: =IF(N123="","",IF(N123=D123,1,0)) -> 0 | P123: =IF(G123="","",J123-G123) -> 0.95533333 | Q123: =IF(G123="","",ABS(P123-Components!$C$2)) -> 1.798 | R123: =IF(G123="","",ABS(P123-Components!$C$3)) -> 3.0806667 | S123: =IF(G123="","",ABS(P123-Components!$C$4)) -> 0.038 | T123: =IF(G123="","",ABS(P123-Components!$C$5)) -> 3.6073333 | U123: =IF(G123="","",ABS(P123-Components!$C$6)) -> 0.20033333 | V123: =IF(G123="","",ABS(P123-Components!$C$7)) -> 0.419 | W123: =IF(G123="","",IF(N123="OK","NONE",INDEX({"S1","S2","W1","W2","N1","N2"},MATCH(MIN(Q123:V123),Q123:V123,0)))) -> W1 | X123: =IF(G123="","",IF(W123=E123,1,0)) -> 0
A124: 122 | B124: 11 | C124: R4 | D124: OK | E124: NONE | F124: K022 | G124: 8.94 | J124: =VLOOKUP(C124,Recipes!$A$2:$N$4,10,FALSE()) -> 9.9053333 | K124: =VLOOKUP(C124,Recipes!$A$2:$N$4,12,FALSE()) -> 0.050137397 | L124: =J124-3*K124 -> 9.7549211 | M124: =J124+3*K124 -> 10.055746 | N124: =IF(G124="","",IF(AND(G124>=L124,G124<=M124),"OK","NG")) -> NG | O124: =IF(N124="","",IF(N124=D124,1,0)) -> 0 | P124: =IF(G124="","",J124-G124) -> 0.96533333 | Q124: =IF(G124="","",ABS(P124-Components!$C$2)) -> 1.788 | R124: =IF(G124="","",ABS(P124-Components!$C$3)) -> 3.0706667 | S124: =IF(G124="","",ABS(P124-Components!$C$4)) -> 0.028 | T124: =IF(G124="","",ABS(P124-Components!$C$5)) -> 3.5973333 | U124: =IF(G124="","",ABS(P124-Components!$C$6)) -> 0.19033333 | V124: =IF(G124="","",ABS(P124-Components!$C$7)) -> 0.409 | W124: =IF(G124="","",IF(N124="OK","NONE",INDEX({"S1","S2","W1","W2","N1","N2"},MATCH(MIN(Q124:V124),Q124:V124,0)))) -> W1 | X124: =IF(G124="","",IF(W124=E124,1,0)) -> 0
